2019-06-10 23:17:46:     User(ID3161410E-aWXZngFf) was authenticated successfully
2019-06-10 23:17:47:     Game type = "Red bonus tile" : True, "Open tanyao" : True, "Game  length" : tonpusen
2019-06-10 23:17:47:     A new game started!
2019-06-10 23:17:47:     The replay link can be found here: http://tenhou.net/0/?log=None&tw=2
2019-06-10 23:17:47:     Players are: [Toul - 新人 - None, COM - 新人 - None, COM - 新人 - None, COM - 新人 - None]
2019-06-10 23:17:48: Unexpected exception
Traceback (most recent call last):
  File "D:\workspace\AIMahjong\myAI\main.py", line 14, in connect_and_play
    return client.start_game()
  File "D:\workspace\AIMahjong\myAI\client\tenhou_client.py", line 119, in start_game
    '<INIT' in msg and self._handle_initial_msg(msg)
  File "D:\workspace\AIMahjong\myAI\client\tenhou_client.py", line 323, in _handle_initial_msg
    self.drawer.init_hand(tiles)
  File "GUI.py", line 288, in init_hand
    self.update_self(hand136, [])
  File "GUI.py", line 622, in update_self
    self._add_tile_image(x, y, tile, 0)
AttributeError: 'TableDisplay' object has no attribute '_add_tile_image'
2019-06-10 23:17:48: End the game...
2019-06-10 23:17:48:     Game was ended unexpected
2019-06-10 23:17:48: 
