2019-06-10 23:18:29:     User(ID3161410E-aWXZngFf) was authenticated successfully
2019-06-10 23:18:31:     Game type = "Red bonus tile" : True, "Open tanyao" : True, "Game  length" : tonpusen
2019-06-10 23:18:31:     A new game started!
2019-06-10 23:18:31:     The replay link can be found here: http://tenhou.net/0/?log=None&tw=1
2019-06-10 23:18:31:     Players are: [Toul - 新人 - None, COM - 新人 - None, COM - 新人 - None, COM - 新人 - None]
2019-06-10 23:18:32: Unexpected exception
Traceback (most recent call last):
  File "D:\workspace\AIMahjong\myAI\main.py", line 14, in connect_and_play
    return client.start_game()
  File "D:\workspace\AIMahjong\myAI\client\tenhou_client.py", line 119, in start_game
    '<INIT' in msg and self._handle_initial_msg(msg)
  File "D:\workspace\AIMahjong\myAI\client\tenhou_client.py", line 323, in _handle_initial_msg
    self.drawer.init_hand(tiles)
  File "GUI.py", line 288, in init_hand
    self.update_self(hand136, [])
  File "GUI.py", line 622, in update_self
    self._add_tile_image(x, y, tile, 0)
  File "GUI.py", line 927, in _add_tile_image
    bt = Button(self.cvs, img = self.photes[player][tile],command=self.hello_world)
  File "C:\Users\YishengYihui\Anaconda3\lib\tkinter\__init__.py", line 2369, in __init__
    Widget.__init__(self, master, 'button', cnf, kw)
  File "C:\Users\YishengYihui\Anaconda3\lib\tkinter\__init__.py", line 2299, in __init__
    (widgetName, self._w) + extra + self._options(cnf))
_tkinter.TclError: unknown option "-img"
2019-06-10 23:18:32: End the game...
2019-06-10 23:18:32:     Game was ended unexpected
2019-06-10 23:18:32: 
